/root/.cache/pypoetry/virtualenvs/chatbot-api-4ke76LwW-py3.12/lib/python3.12/site-packages/pydantic/_internal/_fields.py:132: UserWarning: Field "model_id" in ModelCustomizationCreate has conflict with protected namespace "model_".

You may be able to resolve this warning by setting `model_config['protected_namespaces'] = ()`.
  warnings.warn(
Fetching 5 files:   0%|          | 0/5 [00:00<?, ?it/s]Fetching 5 files: 100%|██████████| 5/5 [00:00<00:00, 15984.39it/s]
Fetching 5 files:   0%|          | 0/5 [00:00<?, ?it/s]Fetching 5 files: 100%|██████████| 5/5 [00:00<00:00, 6436.93it/s]
Fetching 5 files:   0%|          | 0/5 [00:00<?, ?it/s]Fetching 5 files: 100%|██████████| 5/5 [00:00<00:00, 4146.21it/s]
Fetching 5 files:   0%|          | 0/5 [00:00<?, ?it/s]Fetching 5 files: 100%|██████████| 5/5 [00:00<00:00, 6391.81it/s]
Fetching 5 files:   0%|          | 0/5 [00:00<?, ?it/s]Fetching 5 files: 100%|██████████| 5/5 [00:00<00:00, 3138.98it/s]
Fetching 5 files:   0%|          | 0/5 [00:00<?, ?it/s]Fetching 5 files: 100%|██████████| 5/5 [00:00<00:00, 3795.06it/s]
Traceback (most recent call last):
  File "/root/.cache/pypoetry/virtualenvs/chatbot-api-4ke76LwW-py3.12/lib/python3.12/site-packages/sqlalchemy/engine/base.py", line 146, in __init__
    self._dbapi_connection = engine.raw_connection()
                             ^^^^^^^^^^^^^^^^^^^^^^^
  File "/root/.cache/pypoetry/virtualenvs/chatbot-api-4ke76LwW-py3.12/lib/python3.12/site-packages/sqlalchemy/engine/base.py", line 3302, in raw_connection
    return self.pool.connect()
           ^^^^^^^^^^^^^^^^^^^
  File "/root/.cache/pypoetry/virtualenvs/chatbot-api-4ke76LwW-py3.12/lib/python3.12/site-packages/sqlalchemy/pool/base.py", line 449, in connect
    return _ConnectionFairy._checkout(self)
           ^^^^^^^^^^^^^^^^^^^^^^^^^^^^^^^^
  File "/root/.cache/pypoetry/virtualenvs/chatbot-api-4ke76LwW-py3.12/lib/python3.12/site-packages/sqlalchemy/pool/base.py", line 1263, in _checkout
    fairy = _ConnectionRecord.checkout(pool)
            ^^^^^^^^^^^^^^^^^^^^^^^^^^^^^^^^
  File "/root/.cache/pypoetry/virtualenvs/chatbot-api-4ke76LwW-py3.12/lib/python3.12/site-packages/sqlalchemy/pool/base.py", line 712, in checkout
    rec = pool._do_get()
          ^^^^^^^^^^^^^^
  File "/root/.cache/pypoetry/virtualenvs/chatbot-api-4ke76LwW-py3.12/lib/python3.12/site-packages/sqlalchemy/pool/impl.py", line 179, in _do_get
    with util.safe_reraise():
  File "/root/.cache/pypoetry/virtualenvs/chatbot-api-4ke76LwW-py3.12/lib/python3.12/site-packages/sqlalchemy/util/langhelpers.py", line 146, in __exit__
    raise exc_value.with_traceback(exc_tb)
  File "/root/.cache/pypoetry/virtualenvs/chatbot-api-4ke76LwW-py3.12/lib/python3.12/site-packages/sqlalchemy/pool/impl.py", line 177, in _do_get
    return self._create_connection()
           ^^^^^^^^^^^^^^^^^^^^^^^^^
  File "/root/.cache/pypoetry/virtualenvs/chatbot-api-4ke76LwW-py3.12/lib/python3.12/site-packages/sqlalchemy/pool/base.py", line 390, in _create_connection
    return _ConnectionRecord(self)
           ^^^^^^^^^^^^^^^^^^^^^^^
  File "/root/.cache/pypoetry/virtualenvs/chatbot-api-4ke76LwW-py3.12/lib/python3.12/site-packages/sqlalchemy/pool/base.py", line 674, in __init__
    self.__connect()
  File "/root/.cache/pypoetry/virtualenvs/chatbot-api-4ke76LwW-py3.12/lib/python3.12/site-packages/sqlalchemy/pool/base.py", line 900, in __connect
    with util.safe_reraise():
  File "/root/.cache/pypoetry/virtualenvs/chatbot-api-4ke76LwW-py3.12/lib/python3.12/site-packages/sqlalchemy/util/langhelpers.py", line 146, in __exit__
    raise exc_value.with_traceback(exc_tb)
  File "/root/.cache/pypoetry/virtualenvs/chatbot-api-4ke76LwW-py3.12/lib/python3.12/site-packages/sqlalchemy/pool/base.py", line 896, in __connect
    self.dbapi_connection = connection = pool._invoke_creator(self)
                                         ^^^^^^^^^^^^^^^^^^^^^^^^^^
  File "/root/.cache/pypoetry/virtualenvs/chatbot-api-4ke76LwW-py3.12/lib/python3.12/site-packages/sqlalchemy/engine/create.py", line 643, in connect
    return dialect.connect(*cargs, **cparams)
           ^^^^^^^^^^^^^^^^^^^^^^^^^^^^^^^^^^
  File "/root/.cache/pypoetry/virtualenvs/chatbot-api-4ke76LwW-py3.12/lib/python3.12/site-packages/sqlalchemy/engine/default.py", line 621, in connect
    return self.loaded_dbapi.connect(*cargs, **cparams)
           ^^^^^^^^^^^^^^^^^^^^^^^^^^^^^^^^^^^^^^^^^^^^
  File "/root/.cache/pypoetry/virtualenvs/chatbot-api-4ke76LwW-py3.12/lib/python3.12/site-packages/psycopg2/__init__.py", line 122, in connect
    conn = _connect(dsn, connection_factory=connection_factory, **kwasync)
           ^^^^^^^^^^^^^^^^^^^^^^^^^^^^^^^^^^^^^^^^^^^^^^^^^^^^^^^^^^^^^^^
psycopg2.OperationalError: connection to server at "110.74.194.123", port 6000 failed: Connection refused
	Is the server running on that host and accepting TCP/IP connections?


The above exception was the direct cause of the following exception:

Traceback (most recent call last):
  File "/root/.cache/pypoetry/virtualenvs/chatbot-api-4ke76LwW-py3.12/bin/uvicorn", line 8, in <module>
    sys.exit(main())
             ^^^^^^
  File "/root/.cache/pypoetry/virtualenvs/chatbot-api-4ke76LwW-py3.12/lib/python3.12/site-packages/click/core.py", line 1157, in __call__
    return self.main(*args, **kwargs)
           ^^^^^^^^^^^^^^^^^^^^^^^^^^
  File "/root/.cache/pypoetry/virtualenvs/chatbot-api-4ke76LwW-py3.12/lib/python3.12/site-packages/click/core.py", line 1078, in main
    rv = self.invoke(ctx)
         ^^^^^^^^^^^^^^^^
  File "/root/.cache/pypoetry/virtualenvs/chatbot-api-4ke76LwW-py3.12/lib/python3.12/site-packages/click/core.py", line 1434, in invoke
    return ctx.invoke(self.callback, **ctx.params)
           ^^^^^^^^^^^^^^^^^^^^^^^^^^^^^^^^^^^^^^^
  File "/root/.cache/pypoetry/virtualenvs/chatbot-api-4ke76LwW-py3.12/lib/python3.12/site-packages/click/core.py", line 783, in invoke
    return __callback(*args, **kwargs)
           ^^^^^^^^^^^^^^^^^^^^^^^^^^^
  File "/root/.cache/pypoetry/virtualenvs/chatbot-api-4ke76LwW-py3.12/lib/python3.12/site-packages/uvicorn/main.py", line 416, in main
    run(
  File "/root/.cache/pypoetry/virtualenvs/chatbot-api-4ke76LwW-py3.12/lib/python3.12/site-packages/uvicorn/main.py", line 587, in run
    server.run()
  File "/root/.cache/pypoetry/virtualenvs/chatbot-api-4ke76LwW-py3.12/lib/python3.12/site-packages/uvicorn/server.py", line 61, in run
    return asyncio.run(self.serve(sockets=sockets))
           ^^^^^^^^^^^^^^^^^^^^^^^^^^^^^^^^^^^^^^^^
  File "/usr/lib/python3.12/asyncio/runners.py", line 194, in run
    return runner.run(main)
           ^^^^^^^^^^^^^^^^
  File "/usr/lib/python3.12/asyncio/runners.py", line 118, in run
    return self._loop.run_until_complete(task)
           ^^^^^^^^^^^^^^^^^^^^^^^^^^^^^^^^^^^
  File "uvloop/loop.pyx", line 1518, in uvloop.loop.Loop.run_until_complete
  File "/root/.cache/pypoetry/virtualenvs/chatbot-api-4ke76LwW-py3.12/lib/python3.12/site-packages/uvicorn/server.py", line 68, in serve
    config.load()
  File "/root/.cache/pypoetry/virtualenvs/chatbot-api-4ke76LwW-py3.12/lib/python3.12/site-packages/uvicorn/config.py", line 467, in load
    self.loaded_app = import_from_string(self.app)
                      ^^^^^^^^^^^^^^^^^^^^^^^^^^^^
  File "/root/.cache/pypoetry/virtualenvs/chatbot-api-4ke76LwW-py3.12/lib/python3.12/site-packages/uvicorn/importer.py", line 21, in import_from_string
    module = importlib.import_module(module_str)
             ^^^^^^^^^^^^^^^^^^^^^^^^^^^^^^^^^^^
  File "/usr/lib/python3.12/importlib/__init__.py", line 90, in import_module
    return _bootstrap._gcd_import(name[level:], package, level)
           ^^^^^^^^^^^^^^^^^^^^^^^^^^^^^^^^^^^^^^^^^^^^^^^^^^^^
  File "<frozen importlib._bootstrap>", line 1387, in _gcd_import
  File "<frozen importlib._bootstrap>", line 1360, in _find_and_load
  File "<frozen importlib._bootstrap>", line 1331, in _find_and_load_unlocked
  File "<frozen importlib._bootstrap>", line 935, in _load_unlocked
  File "<frozen importlib._bootstrap_external>", line 995, in exec_module
  File "<frozen importlib._bootstrap>", line 488, in _call_with_frames_removed
  File "/home/sokheang/chatbot_project_api/api_chatbot_project/app/server.py", line 34, in <module>
    Base.metadata.create_all(bind=database.engine)
  File "/root/.cache/pypoetry/virtualenvs/chatbot-api-4ke76LwW-py3.12/lib/python3.12/site-packages/sqlalchemy/sql/schema.py", line 5868, in create_all
    bind._run_ddl_visitor(
  File "/root/.cache/pypoetry/virtualenvs/chatbot-api-4ke76LwW-py3.12/lib/python3.12/site-packages/sqlalchemy/engine/base.py", line 3252, in _run_ddl_visitor
    with self.begin() as conn:
  File "/usr/lib/python3.12/contextlib.py", line 137, in __enter__
    return next(self.gen)
           ^^^^^^^^^^^^^^
  File "/root/.cache/pypoetry/virtualenvs/chatbot-api-4ke76LwW-py3.12/lib/python3.12/site-packages/sqlalchemy/engine/base.py", line 3242, in begin
    with self.connect() as conn:
         ^^^^^^^^^^^^^^
  File "/root/.cache/pypoetry/virtualenvs/chatbot-api-4ke76LwW-py3.12/lib/python3.12/site-packages/sqlalchemy/engine/base.py", line 3278, in connect
    return self._connection_cls(self)
           ^^^^^^^^^^^^^^^^^^^^^^^^^^
  File "/root/.cache/pypoetry/virtualenvs/chatbot-api-4ke76LwW-py3.12/lib/python3.12/site-packages/sqlalchemy/engine/base.py", line 148, in __init__
    Connection._handle_dbapi_exception_noconnection(
  File "/root/.cache/pypoetry/virtualenvs/chatbot-api-4ke76LwW-py3.12/lib/python3.12/site-packages/sqlalchemy/engine/base.py", line 2442, in _handle_dbapi_exception_noconnection
    raise sqlalchemy_exception.with_traceback(exc_info[2]) from e
  File "/root/.cache/pypoetry/virtualenvs/chatbot-api-4ke76LwW-py3.12/lib/python3.12/site-packages/sqlalchemy/engine/base.py", line 146, in __init__
    self._dbapi_connection = engine.raw_connection()
                             ^^^^^^^^^^^^^^^^^^^^^^^
  File "/root/.cache/pypoetry/virtualenvs/chatbot-api-4ke76LwW-py3.12/lib/python3.12/site-packages/sqlalchemy/engine/base.py", line 3302, in raw_connection
    return self.pool.connect()
           ^^^^^^^^^^^^^^^^^^^
  File "/root/.cache/pypoetry/virtualenvs/chatbot-api-4ke76LwW-py3.12/lib/python3.12/site-packages/sqlalchemy/pool/base.py", line 449, in connect
    return _ConnectionFairy._checkout(self)
           ^^^^^^^^^^^^^^^^^^^^^^^^^^^^^^^^
  File "/root/.cache/pypoetry/virtualenvs/chatbot-api-4ke76LwW-py3.12/lib/python3.12/site-packages/sqlalchemy/pool/base.py", line 1263, in _checkout
    fairy = _ConnectionRecord.checkout(pool)
            ^^^^^^^^^^^^^^^^^^^^^^^^^^^^^^^^
  File "/root/.cache/pypoetry/virtualenvs/chatbot-api-4ke76LwW-py3.12/lib/python3.12/site-packages/sqlalchemy/pool/base.py", line 712, in checkout
    rec = pool._do_get()
          ^^^^^^^^^^^^^^
  File "/root/.cache/pypoetry/virtualenvs/chatbot-api-4ke76LwW-py3.12/lib/python3.12/site-packages/sqlalchemy/pool/impl.py", line 179, in _do_get
    with util.safe_reraise():
  File "/root/.cache/pypoetry/virtualenvs/chatbot-api-4ke76LwW-py3.12/lib/python3.12/site-packages/sqlalchemy/util/langhelpers.py", line 146, in __exit__
    raise exc_value.with_traceback(exc_tb)
  File "/root/.cache/pypoetry/virtualenvs/chatbot-api-4ke76LwW-py3.12/lib/python3.12/site-packages/sqlalchemy/pool/impl.py", line 177, in _do_get
    return self._create_connection()
           ^^^^^^^^^^^^^^^^^^^^^^^^^
  File "/root/.cache/pypoetry/virtualenvs/chatbot-api-4ke76LwW-py3.12/lib/python3.12/site-packages/sqlalchemy/pool/base.py", line 390, in _create_connection
    return _ConnectionRecord(self)
           ^^^^^^^^^^^^^^^^^^^^^^^
  File "/root/.cache/pypoetry/virtualenvs/chatbot-api-4ke76LwW-py3.12/lib/python3.12/site-packages/sqlalchemy/pool/base.py", line 674, in __init__
    self.__connect()
  File "/root/.cache/pypoetry/virtualenvs/chatbot-api-4ke76LwW-py3.12/lib/python3.12/site-packages/sqlalchemy/pool/base.py", line 900, in __connect
    with util.safe_reraise():
  File "/root/.cache/pypoetry/virtualenvs/chatbot-api-4ke76LwW-py3.12/lib/python3.12/site-packages/sqlalchemy/util/langhelpers.py", line 146, in __exit__
    raise exc_value.with_traceback(exc_tb)
  File "/root/.cache/pypoetry/virtualenvs/chatbot-api-4ke76LwW-py3.12/lib/python3.12/site-packages/sqlalchemy/pool/base.py", line 896, in __connect
    self.dbapi_connection = connection = pool._invoke_creator(self)
                                         ^^^^^^^^^^^^^^^^^^^^^^^^^^
  File "/root/.cache/pypoetry/virtualenvs/chatbot-api-4ke76LwW-py3.12/lib/python3.12/site-packages/sqlalchemy/engine/create.py", line 643, in connect
    return dialect.connect(*cargs, **cparams)
           ^^^^^^^^^^^^^^^^^^^^^^^^^^^^^^^^^^
  File "/root/.cache/pypoetry/virtualenvs/chatbot-api-4ke76LwW-py3.12/lib/python3.12/site-packages/sqlalchemy/engine/default.py", line 621, in connect
    return self.loaded_dbapi.connect(*cargs, **cparams)
           ^^^^^^^^^^^^^^^^^^^^^^^^^^^^^^^^^^^^^^^^^^^^
  File "/root/.cache/pypoetry/virtualenvs/chatbot-api-4ke76LwW-py3.12/lib/python3.12/site-packages/psycopg2/__init__.py", line 122, in connect
    conn = _connect(dsn, connection_factory=connection_factory, **kwasync)
           ^^^^^^^^^^^^^^^^^^^^^^^^^^^^^^^^^^^^^^^^^^^^^^^^^^^^^^^^^^^^^^^
sqlalchemy.exc.OperationalError: (psycopg2.OperationalError) connection to server at "110.74.194.123", port 6000 failed: Connection refused
	Is the server running on that host and accepting TCP/IP connections?

(Background on this error at: https://sqlalche.me/e/20/e3q8)
/root/.cache/pypoetry/virtualenvs/chatbot-api-4ke76LwW-py3.12/lib/python3.12/site-packages/pydantic/_internal/_fields.py:132: UserWarning: Field "model_id" in ModelCustomizationCreate has conflict with protected namespace "model_".

You may be able to resolve this warning by setting `model_config['protected_namespaces'] = ()`.
  warnings.warn(
Fetching 5 files:   0%|          | 0/5 [00:00<?, ?it/s]Fetching 5 files: 100%|██████████| 5/5 [00:00<00:00, 8518.08it/s]
Fetching 5 files:   0%|          | 0/5 [00:00<?, ?it/s]Fetching 5 files: 100%|██████████| 5/5 [00:00<00:00, 3607.07it/s]
Fetching 5 files:   0%|          | 0/5 [00:00<?, ?it/s]Fetching 5 files: 100%|██████████| 5/5 [00:00<00:00, 6880.42it/s]
Fetching 5 files:   0%|          | 0/5 [00:00<?, ?it/s]Fetching 5 files: 100%|██████████| 5/5 [00:00<00:00, 9358.11it/s]
Fetching 5 files:   0%|          | 0/5 [00:00<?, ?it/s]Fetching 5 files: 100%|██████████| 5/5 [00:00<00:00, 6411.35it/s]
Fetching 5 files:   0%|          | 0/5 [00:00<?, ?it/s]Fetching 5 files: 100%|██████████| 5/5 [00:00<00:00, 14990.36it/s]
INFO:     Started server process [1541251]
INFO:     Waiting for application startup.

 __          ___      .__   __.   _______      _______. _______ .______     ____    ____  _______
|  |        /   \     |  \ |  |  /  _____|    /       ||   ____||   _  \    \   \  /   / |   ____|
|  |       /  ^  \    |   \|  | |  |  __     |   (----`|  |__   |  |_)  |    \   \/   /  |  |__
|  |      /  /_\  \   |  . `  | |  | |_ |     \   \    |   __|  |      /      \      /   |   __|
|  `----./  _____  \  |  |\   | |  |__| | .----)   |   |  |____ |  |\  \----.  \    /    |  |____
|_______/__/     \__\ |__| \__|  \______| |_______/    |_______|| _| `._____|   \__/     |_______|

[1;32;40mLANGSERVE:[0m See all available routes at /docs/

[1;31;40mLANGSERVE:[0m ⚠️ Using pydantic 2.9.2. OpenAPI docs for invoke, batch, stream, stream_log endpoints will not be generated. API endpoints and playground should work as expected. If you need to see the docs, you can downgrade to pydantic 1. For example, `pip install pydantic==1.10.13`. See https://github.com/tiangolo/fastapi/issues/10360 for details.

INFO:     Application startup complete.
INFO:     Uvicorn running on http://127.0.0.1:8085 (Press CTRL+C to quit)
INFO:     127.0.0.1:37990 - "GET /docs HTTP/1.1" 200 OK
INFO:     127.0.0.1:37990 - "GET /openapi.json HTTP/1.1" 200 OK
INFO:     127.0.0.1:49254 - "GET / HTTP/1.1" 307 Temporary Redirect
INFO:     127.0.0.1:44146 - "POST /suggestion_chatbot/invoke HTTP/1.1" 400 Bad Request
Number of requested results 20 is greater than number of elements in index 3, updating n_results = 3
INFO:     127.0.0.1:44632 - "POST /suggestion_chatbot/invoke HTTP/1.1" 200 OK
Number of requested results 20 is greater than number of elements in index 3, updating n_results = 3
INFO:     127.0.0.1:54766 - "POST /suggestion_chatbot/invoke HTTP/1.1" 200 OK
